Workbook

Sheet MARKUP
A1: System | B1: Discount | C1: Markup | Z1: (cumulative)
A2: Window Profile | B2: -0.65 | C2: 1.08 | Z2: =(1+B2)*(1+C2)-1 -> -27.20%
A3: Window Hardware | B3: -0.65 | C3: 1.08 | Z3: =(1+B3)*(1+C3)-1 -> -27.20%
A4: Bifold Profile | B4: -0.65 | C4: 0.9 | Z4: =(1+B4)*(1+C4)-1 -> -33.50%
A5: Bifold Hardware | B5: -0.55 | C5: 0.9 | Z5: =(1+B5)*(1+C5)-1 -> -14.50%
A6: Slider Profile | B6: -0.65 | C6: 1.15 | Z6: =(1+B6)*(1+C6)-1 -> -24.75%
A7: Slider Hardware | B7: -0.65 | C7: 1.15 | Z7: =(1+B7)*(1+C7)-1 -> -24.75%
A8: Internal Bifold | B8: -0.55 | C8: 0.9 | Z8: =(1+B8)*(1+C8)-1 -> -14.50%
A9: Internal Slider | B9: -0.55 | C9: 0.9 | Z9: =(1+B9)*(1+C9)-1 -> -14.50%
A10: Composite | B10: -0.55 | C10: 0.9 | Z10: =(1+B10)*(1+C10)-1 -> -14.50%
A11: Ultra Slider Profile | B11: -0.7 | C11: 1.15
A12: Ultra Slider Hardware | B12: -0.7 | C12: 1.15

Sheet bifold
A1: type | B1: values | D1: before discount | F1: markup
A2: bifold_leaf | B2: 395
A3: french_fixed | B3: 0
A4: single_fixed | B4: 100
A5: bifold_cill_90 | B5: =D5*(1+F5) -> 17.29 | D5: 26 | F5: =MARKUP!$Z$4 -> -33.50%
A6: bifold_cill_150 | B6: =D6*(1+F6) -> 26.6 | D6: 40 | F6: =MARKUP!$Z$4 -> -33.50%
A7: bifold_cill_180 | B7: =D7*(1+F7) -> 28.595 | D7: 43 | F7: =MARKUP!$Z$4 -> -33.50%
A8: bifold_cill_230 | B8: =D8*(1+F8) -> 32.585 | D8: 49 | F8: =MARKUP!$Z$4 -> -33.50%
A9: bifold_handle_grey | B9: 0 | D9: 18 | F9: =MARKUP!$Z$5 -> -14.50%
A10: bifold_handle_black | B10: 0 | D10: 18 | F10: =MARKUP!$Z$5 -> -14.50%
A11: bifold_handle_white | B11: 0 | D11: 18 | F11: =MARKUP!$Z$5 -> -14.50%
A12: bifold_handle_chrome | B12: =D12*(1+F12) -> 30.78 | D12: 36 | F12: =MARKUP!$Z$5 -> -14.50%
A13: bifold_handle_satin | B13: =D13*(1+F13) -> 36.765 | D13: 43 | F13: =MARKUP!$Z$5 -> -14.50%
A14: bifold_handle_gold | B14: =D14*(1+F14) -> 36.765 | D14: 43 | F14: =MARKUP!$Z$5 -> -14.50%
A15: bifold_handle_rose_gold | B15: =D15*(1+F15) -> 36.765 | D15: 43 | F15: =MARKUP!$Z$5 -> -14.50%
A16: bifold_handle_dual | B16: =D16*(1+F16) -> 36.765 | D16: 43 | F16: =MARKUP!$Z$5 -> -14.50%
A17: bifold_handle_coastal_stainless_steel | B17: =D17*(1+F17) -> 94.05 | D17: 110 | F17: =MARKUP!$Z$5 -> -14.50%
A18: bifold_floating_corner | B18: 75
A19: bifold_adjustable_jamb | B19: 100
A20: bifold_toe_heel_adjuster | B20: 0
A21: bifold_trickle_vent | B21: 15
A22: bifold_addon_20 | B22: =D22*(1+F22) -> 16.625 | D22: 25 | F22: =MARKUP!$Z$4 -> -33.50%
A23: bifold_addon_38 | B23: =D23*(1+F23) -> 21.945 | D23: 33 | F23: =MARKUP!$Z$4 -> -33.50%
A24: bifold_ral | B24: 250
A25: bifold_second_ral | B25: 0
A26: astragal_bar_fixed | B26: 50
A27: transom_bar_fixed | B27: 50
A28: blinds | B28: 200
A29: sidelight_frame | B29: 30
A30: sidelight_frame_fixed | B30: 0
A31: ult_bifold_low_e_tuff_per_pane | B31: 55 | C31: comes from options tab partsStrategy

Sheet patio
A1: type | B1: values | D1: before discount | F1: markup
A2: patio_cill_230 | B2: =D2*(1+F2) -> 42.5915 | D2: 56.6 | F2: =MARKUP!$Z$6 -> -24.75%
A3: patio_cill_250 | B3: =D3*(1+F3) -> 48.724375 | D3: 64.75 | F3: =MARKUP!$Z$6 -> -24.75%
A4: patio_lift_slide_uplift | B4: 200 | F4: =MARKUP!$Z$7 -> -24.75%
A5: patio_trickle_vent | B5: 40 | F5: =MARKUP!$Z$7 -> -24.75%
A6: patio_additional_slide | B6: =D6*(1+F6) -> 0 | F6: =MARKUP!$Z$7 -> -24.75%
A7: patio_monorail_fixed | B7: =D7*(1+F7) -> 0 | F7: =MARKUP!$Z$7 -> -24.75%
A8: patio_addon_35 | B8: =D8*(1+F8) -> 30.1 | D8: 40 | F8: =MARKUP!$Z$6 -> -24.75%
A9: patio_handle_gold | B9: =D9*(1+F9) -> 53.4275 | D9: 71 | F9: =MARKUP!$Z$7 -> -24.75%
A10: patio_handle_smoke_chrome | B10: =D10*(1+F10) -> 63.21 | D10: 84 | F10: =MARKUP!$Z$7 -> -24.75%
A11: patio_handle_satin | B11: =D11*(1+F11) -> 45.9025 | D11: 61 | F11: =MARKUP!$Z$7 -> -24.75%
A12: patio_handle_black | B12: =D12*(1+F12) -> 25.585 | D12: 34 | F12: =MARKUP!$Z$7 -> -24.75%
A13: patio_handle_white | B13: =D13*(1+F13) -> 25.585 | D13: 34 | F13: =MARKUP!$Z$7 -> -24.75%
A14: patio_handle_chrome | B14: =D14*(1+F14) -> 52.675 | C14: (this is Polished Chrome) | D14: 70 | F14: =MARKUP!$Z$7 -> -24.75%
A15: patio_handle_coastal_steel | B15: =D15*(1+F15) -> 167.055 | D15: 222 | F15: =MARKUP!$Z$7 -> -24.75%
A16: patio_handle_coastal_black | B16: =D16*(1+F16) -> 312.2875 | D16: 415 | F16: =MARKUP!$Z$7 -> -24.75%
A17: patio_handle_l&s_white | B17: =D17*(1+F17) -> 79.765 | D17: 106 | F17: =MARKUP!$Z$7 -> -24.75%
A18: patio_handle_l&s_black | B18: =D18*(1+F18) -> 79.765 | D18: 106 | F18: =MARKUP!$Z$7 -> -24.75%
A19: patio_ral | B19: 300
A20: patio_second_ral | B20: 0

Sheet cortizo_patio
A1: type | B1: values
A2: cortizo_patio_cill_180 | B2: 37.639
A3: cortizo_patio_cill_230 | B3: =patio!B2 -> 42.5915
A4: cortizo_patio_cill_250 | B4: =patio!B3 -> 48.724375
A5: cortizo_patio_trickle_vent | B5: =patio!B5 -> 40
A6: cortizo_patio_additional_slide | B6: =patio!B6 -> 0
A7: cortizo_patio_addon_35 | B7: =patio!B8 -> 30.1
A8: cortizo_patio_ral | B8: =patio!B19 -> 300
A9: cortizo_patio_second_ral | B9: =patio!B20 -> 0
A10: cortizo_patio_handle_grey | B10: =B11 -> 25.585
A11: cortizo_patio_handle_black | B11: =patio!B12 -> 25.585
A12: cortizo_patio_handle_white | B12: =patio!B13 -> 25.585

Sheet window
A1: type | B1: values | D1: before discount | F1: markup
A2: window_sash_per_m | B2: =D2*(1+F2) -> 22.48792 | D2: 30.89 | F2: =MARKUP!$Z$2 -> -27.20%
A3: window_sash_fixed | B3: =D3*(1+F3) -> 12.8856 | D3: 17.7 | F3: =MARKUP!$Z$3 -> -27.20%
A4: window_opener_fixed | B4: =D4*(1+F4) -> 38.78784 | D4: 53.28 | F4: =MARKUP!$Z$3 -> -27.20%
A5: window_bar_per_m | B5: =D5*(1+F5) -> 22.48792 | D5: 30.89 | F5: =MARKUP!$Z$2 -> -27.20%
A6: window_frame_per_m | B6: =D6*(1+F6) -> 23.90752 | D6: 32.84 | F6: =MARKUP!$Z$2 -> -27.20%
A7: window_frame_fixed | B7: =D7*(1+F7) -> 9.62416 | D7: 13.22 | F7: =MARKUP!$Z$3 -> -27.20%
A8: window_bar_fixed | B8: =D8*(1+F8) -> 2.3296 | D8: 3.2 | F8: =MARKUP!$Z$2 -> -27.20%
A9: window_bead_per_m | B9: =D9*(1+F9) -> 5.64928 | D9: 7.76 | F9: =MARKUP!$Z$2 -> -27.20%
A10: window_sash_tilt_per_m | B10: =D10*(1+F10) -> 24.0604 | D10: 33.05 | F10: =MARKUP!$Z$2 -> -27.20%
A11: window_sash_tilt_fixed | B11: =D11*(1+F11) -> 12.8856 | D11: 17.7 | F11: =MARKUP!$Z$3 -> -27.20%
A12: window_opener_tilt_fixed | B12: =D12*(1+F12) -> 158.62392 | D12: 217.89 | F12: =MARKUP!$Z$3 -> -27.20%
A13: window_bar_tilt_per_m | B13: =D13*(1+F13) -> 22.48792 | D13: 30.89 | F13: =MARKUP!$Z$2 -> -27.20%
A14: window_frame_tilt_per_m | B14: =D14*(1+F14) -> 24.47536 | D14: 33.62 | F14: =MARKUP!$Z$2 -> -27.20%
A15: window_sash_flush_per_m | B15: =D15*(1+F15) -> 22.48792 | D15: 30.89 | F15: =MARKUP!$Z$2 -> -27.20%
A16: window_sash_flush_fixed | B16: =D16*(1+F16) -> 12.8856 | D16: 17.7 | F16: =MARKUP!$Z$3 -> -27.20%
A17: window_opener_flush_fixed | B17: =D17*(1+F17) -> 38.78784 | D17: 53.28 | F17: =MARKUP!$Z$3 -> -27.20%
A18: window_bar_flush_per_m | B18: =D18*(1+F18) -> 22.48792 | D18: 30.89 | F18: =MARKUP!$Z$2 -> -27.20%
A19: window_frame_flush_per_m | B19: =D19*(1+F19) -> 23.90752 | D19: 32.84 | F19: =MARKUP!$Z$2 -> -27.20%
A20: window_cill_90 | B20: =D20*(1+F20) -> 16.4892 | D20: 22.65 | F20: =MARKUP!$Z$2 -> -27.20%
A21: window_cill_150 | B21: =D21*(1+F21) -> 22.83008 | D21: 31.36 | F21: =MARKUP!$Z$2 -> -27.20%
A22: window_cill_180 | B22: =D22*(1+F22) -> 26.52832 | D22: 36.44 | F22: =MARKUP!$Z$2 -> -27.20%
A23: window_cill_230 | B23: =D23*(1+F23) -> 31.10744 | D23: 42.73 | F23: =MARKUP!$Z$2 -> -27.20%
A24: window_addon_20 | B24: =D24*(1+F24) -> 13.45344 | D24: 18.48 | F24: =MARKUP!$Z$2 -> -27.20%
A25: window_addon_38 | B25: =D25*(1+F25) -> 15.88496 | D25: 21.82 | F25: =MARKUP!$Z$2 -> -27.20%
A26: window_hooded_vent | B26: =D26*(1+F26) -> 19.19008 | D26: 26.36 | F26: =MARKUP!$Z$2 -> -27.20%
A27: window_trickle_vent | B27: 15
A28: window_handle_black_casement | B28: =D28*(1+F28) -> 4.53544 | D28: 6.23 | F28: =MARKUP!$Z$3 -> -27.20%
A29: window_handle_chrome_casement | B29: =D29*(1+F29) -> 9.07816 | D29: 12.47 | F29: =MARKUP!$Z$3 -> -27.20%
A30: window_handle_gold_casement | B30: =D30*(1+F30) -> 9.07816 | D30: 12.47 | F30: =MARKUP!$Z$3 -> -27.20%
A31: window_handle_steel_casement | B31: =D31*(1+F31) -> 9.07816 | D31: 12.47 | F31: =MARKUP!$Z$3 -> -27.20%
A32: window_handle_white_casement | B32: =D32*(1+F32) -> 4.53544 | D32: 6.23 | F32: =MARKUP!$Z$3 -> -27.20%
A33: window_handle_coastal_steel_casement | B33: =D33*(1+F33) -> 75.166 | D33: 103.25 | F33: =MARKUP!$Z$3 -> -27.20%
A34: window_handle_coastal_black_casement | B34: =D34*(1+F34) -> 63.52528 | D34: 87.26 | F34: =MARKUP!$Z$3 -> -27.20%
A35: window_handle_black_tilt_turn | B35: =D35*(1+F35) -> 8.4084 | D35: 11.55 | F35: =MARKUP!$Z$3 -> -27.20%
A36: window_handle_chrome_tilt_turn | B36: =D36*(1+F36) -> 15.82672 | D36: 21.74 | F36: =MARKUP!$Z$3 -> -27.20%
A37: window_handle_gold_tilt_turn | B37: =D37*(1+F37) -> 15.82672 | D37: 21.74 | F37: =MARKUP!$Z$3 -> -27.20%
A38: window_handle_steel_tilt_turn | B38: =D38*(1+F38) -> 15.82672 | D38: 21.74 | F38: =MARKUP!$Z$3 -> -27.20%
A39: window_handle_white_tilt_turn | B39: =D39*(1+F39) -> 8.4084 | D39: 11.55 | F39: =MARKUP!$Z$3 -> -27.20%
... A41: window_handle_coastal_black_tilt_turn | B41: =D41*(1+F41) -> 62.14936 | D41: 85.37 | F41: =MARKUP!$Z$3 -> -27.20%
...

Sheet glass
A1: type | B1: values
A2: glass_low_e | B2: 49
A3: glass_low_e_oversized | B3: 20
A4: glass_low_e_tuff | B4: 49
A5: glass_low_e_tuff_oversized | B5: 20
A6: glass_low_e_one | B6: 56
A7: glass_low_e_one_oversized | B7: 20
A8: glass_low_e_one_tuff | B8: 56
A9: glass_low_e_one_tuff_oversized | B9: 20
A10: glass_laminated_6.8 | B10: 82
A11: glass_laminated_6.8_oversized | B11: 20
A12: glass_laminated_6.8_tuff | B12: 82
A13: glass_laminated_6.8_tuff_oversized | B13: 20
... A43: glass_pattern_SAT_tuff | B43: 30

Sheet upvc_window
A1: type | B1: values
A2: upvc_window_sash_per_m | B2: 6
A3: upvc_window_sash_fixed | B3: 4
A4: upvc_window_opener_fixed | B4: 8.75
A5: upvc_window_frame_per_m | B5: 4.75
A6: upvc_window_bar_per_m | B6: 5.5
A7: upvc_window_bead_per_m | B7: 1
A8: upvc_window_frame_fixed | B8: 2.5
A9: upvc_cill_standard_85 | B9: 20
A10: upvc_cill_standard_125 | B10: 25
A11: upvc_cill_standard_150 | B11: 30
A12: upvc_cill_standard_180 | B12: 35
A13: upvc_cill_standard_225 | B13: 40

Sheet values
A1: type | B1: values
A2: upvc_door_single | B2: 200
A3: upvc_door_french | B3: 400

Sheet composite
A1: type | B1: values | E1: before discount
A2: AbercornSlab | B2: {=E2:E495*(1+MARKUP!$Z$10)} -> 664.27 | E2: 776.92308
A3: AbercornUltimateSlab | B3: 689.20892 | E3: 806.09231
A4: CornwallSlab | B4: 585.74077 | E4: 685.07692
A5: CambridgeSlab | B5: 533.07277 | E5: 623.47692
A6: CornwallUltimateSlab | B6: 606.06346 | E6: 708.84615
A7: WhitmoreSolidSlab | B7: 533.07277 | E7: 623.47692
A8: NorfolkSolidSlab | B8: 532.152 | E8: 622.4
A9: AstonSolidSlab | B9: 533.07277 | E9: 623.47692
A10: MiddletonSolidSlab | B10: 533.07277 | E10: 623.47692
A11: MiddletonGlazed4Slab | B11: 631.93708 | E11: 739.10769
A12: WinslowSolidSlab | B12: 533.07277 | E12: 623.47692
A13: Winslow3Slab | B13: 658.73146 | E13: 770.44615
A14: ElmhurstSlab | B14: 606.06346 | E14: 708.84615
... A31: OpenOut | B31: 32.332154 | E31: 37.815385
A32: Cill1 | B32: 9.6286154 | C32: pm | E32: 11.261538
A33: Cill2 | B33: 15.416308 | C33: pm | E33: 18.030769
A34: Cill3 | B34: 17.586692 | C34: pm | E34: 20.569231
A35: AM3Threshold | B35: 32.174308 | E35: 37.630769
A36: AM370Threshold | B36: 27.688846 | E36: 32.384615
A37: Addons1 | B37: 5.7482308 | C37: pm | E37: 6.7230769
A38: Addons2 | B38: 14.153538 | C38: pm | E38: 16.553846
A39: Addons3 | B39: 16.258154 | C39: pm | E39: 19.015385
A40: StandardAstonGlass | B40: 21.296077 | E40: 24.907692
A41: StandardBramptonGlass | B41: 10.641462 | E41: 12.446154
A42: StandardMiddleton4Glass | B42: 42.605308 | E42: 49.830769
A43: StandardWinslow3Glass | B43: 34.620923 | E43: 40.492308
A44: StandardElmhurstGlass | B44: 21.296077 | E44: 24.907692
A45: StandardHattonGlass | B45: 27.531 | E45: 32.2
A46: StandardAxwellGlass | B46: 12.075231 | E46: 14.123077
A47: StandardBuxtonGlass | B47: 21.743308 | E47: 25.430769
A48: StandardGraftonGlass | B48: 27.162692 | E48: 31.769231
A49: StandardWalcotGlass | B49: 27.965077 | E49: 32.707692
A50: StandardRutlandGlass | B50: 12.338308 | E50: 14.430769
A51: StandardSomersetGlass | B51: 10.641462 | E51: 12.446154
... A462: StandardCornwallGlass | B462: 10.641462 | E462: 12.446154
A463: composite_sidelight_bar_g1 | B463: 16.39035 | E463: 19.17
A464: composite_sidelight_bar_g2 | B464: 24.111 | E464: 28.20
A465: composite_sidelight_bar_g3 | B465: 27.7533 | E465: 32.46
A466: composite_sidelight_coupler_g1 | B466: 25.1541 | E466: 29.42
...

Sheet price_files
A1: type | B1: pricefile | C1: trade/trade/retail
A2: name | B2: id | C2: delivery charge | D2: all markup | E2: aluminium markup | F2: upvc markup | G2: glass markup | H2: composite markup | I2: overrides
A3: Trade | B3: trade | C3: No | I3: =IFERROR(__xludf.DUMMYFUNCTION("IFERROR(TEXTJOIN(""/"", TRUE, FILTER('(price file overrides)'!$B$2:$B995 & ""="" & '(price file overrides)'!$C$2:$C995, '(price file overrides)'!$A$2:$A995 = B3)), """") "),"")
A4: Partner | B4: partner | C4: No | D4: -10 | I4: =IFERROR(__xludf.DUMMYFUNCTION("IFERROR(TEXTJOIN(""/"", TRUE, FILTER('(price file overrides)'!$B$2:$B995 & ""="" & '(price file overrides)'!$C$2:$C995, '(price file overrides)'!$A$2:$A995 = B4)), """") "),"")
A5: Retail | B5: retail | C5: No | D5: 10 | I5: =IFERROR(__xludf.DUMMYFUNCTION("IFERROR(TEXTJOIN(""/"", TRUE, FILTER('(price file overrides)'!$B$2:$B995 & ""="" & '(price file overrides)'!$C$2:$C995, '(price file overrides)'!$A$2:$A995 = B5)), """") "),"")

Sheet (price file overrides)
A1: price file | B1: pricing key | C1: value

Sheet (patio_costs)
C2: patio_2_
B3: 1500 | C3: 1600 | D3: 1700 | E3: 1800 | F3: 1900 | G3: 2000 | H3: 2100 | I3: 2200 | J3: 2300 | K3: 2400 | L3: 2500 | M3: 2600 | N3: 2700 | O3: 2800 | P3: 2900 | Q3: 3000 | R3: 3100 | S3: 3200 | T3: 3300 | U3: 3400 | V3: 3500 | W3: 3600 | X3: 3700 | Y3: 3800 | Z3: 3900 | AA3: 4000 | AB3: 4100 | AC3: 4200 | AD3: 4300 | AE3: 4400 | AF3: 4500 | AG3: 4600 | AH3: 4700 | AI3: 4800 | AJ3: 4900 | AK3: 5000
A4: 2000 | B4: 1476.0865 | C4: 1503.9421 | D4: 1531.7977 | E4: 1559.6533 | F4: 1587.5089 | G4: 1615.3645 | H4: 1643.2201 | I4: 1671.0756 | J4: 1699.6378 | K4: 1727.4933 | L4: 1755.3489 | M4: 1783.2045 | N4: 1811.0601 | O4: 1838.9157 | P4: 1866.7609 | Q4: 1894.6165 | R4: 1922.4721 | S4: 1951.0342 | T4: 1978.8898 | U4: 2006.7454 | V4: 2054.903 | W4: 2082.7586 | X4: 2110.6142 | Y4: 2138.4698 | Z4: 2166.3254 | AA4: 2194.181 | AB4: 2222.7431 | AC4: 2250.5987 | AD4: 2278.4543 | AE4: 2306.2995 | AF4: 2334.1551 | AG4: 2362.0106 | AH4: 2389.8662 | AI4: 2417.7218 | AJ4: 2445.5774 | AK4: 2474.1395
A5: 2100 | B5: 1514.1659 | C5: 1542.0215 | D5: 1569.877 | E5: 1597.7326 | F5: 1625.5882 | G5: 1653.4438 | H5: 1681.2994 | I5: 1709.155 | J5: 1737.7171 | K5: 1765.5727 | L5: 1793.4283 | M5: 1821.2839 | N5: 1849.1291 | O5: 1876.9847 | P5: 1904.8403 | Q5: 1932.6959 | R5: 1960.5514 | S5: 1989.1135 | T5: 2037.2712 | U5: 2065.1268 | V5: 2092.9824 | W5: 2120.838 | X5: 2148.6936 | Y5: 2176.5491 | Z5: 2204.4047 | AA5: 2232.2603 | AB5: 2260.8224 | AC5: 2288.6676 | AD5: 2316.5232 | AE5: 2344.3788 | AF5: 2372.2344 | AG5: 2400.09 | AH5: 2427.9456 | AI5: 2455.8012 | AJ5: 2483.6568 | AK5: 2512.2189
A6: 2200 | B6: 1552.2452 | C6: 1580.1008 | D6: 1607.9564 | E6: 1635.812 | F6: 1663.6676 | G6: 1691.5232 | H6: 1719.3788 | I6: 1747.2343 | J6: 1775.7965 | K6: 1803.652 | L6: 1831.4972 | M6: 1859.3528 | N6: 1887.2084 | O6: 1915.064 | P6: 1942.9196 | Q6: 1970.7752 | R6: 1998.6308 | S6: 2047.495 | T6: 2075.3506 | U6: 2103.2061 | V6: 2131.0617 | W6: 2158.9173 | X6: 2186.7729 | Y6: 2214.6285 | Z6: 2242.4841 | AA6: 2270.3293 | AB6: 2298.8914 | AC6: 2326.747 | AD6: 2354.6026 | AE6: 2382.4582 | AF6: 2410.3138 | AG6: 2438.1694 | AH6: 2466.0249 | AI6: 2493.8805 | AJ6: 2521.7361 | AK6: 2550.2982
A7: 2300 | B7: 1590.3246 | C7: 1618.1802 | D7: 1646.0357 | E7: 1673.8913 | F7: 1701.7469 | G7: 1729.6025 | H7: 1757.4581 | I7: 1785.3137 | J7: 1813.8654 | K7: 1841.721 | L7: 1869.5766 | M7: 1897.4322 | N7: 1925.2878 | O7: 1953.1434 | P7: 1980.999 | Q7: 2029.1566 | R7: 2057.0122 | S7: 2085.5743 | T7: 2113.4299 | U7: 2141.2855 | V7: 2169.1411 | W7: 2196.9967 | X7: 2224.8523 | Y7: 2252.6975 | Z7: 2280.553 | AA7: 2308.4086 | AB7: 2336.9707 | AC7: 2364.8263 | AD7: 2392.6819 | AE7: 2420.5375 | AF7: 2448.3931 | AG7: 2476.2487 | AH7: 2504.1043 | AI7: 2531.9599 | AJ7: 2559.8155 | AK7: 2588.3776
A8: 2400 | B8: 1628.4039 | C8: 1656.2595 | D8: 1684.1151 | E8: 1711.9707 | F8: 1739.8263 | G8: 1767.6819 | H8: 1795.5271 | I8: 1823.3827 | J8: 1851.9448 | K8: 1879.8004 | L8: 1907.6559 | M8: 1935.5115 | N8: 1963.3671 | O8: 1991.2227 | P8: 2039.3804 | Q8: 2067.236 | R8: 2095.0916 | S8: 2123.6537 | T8: 2151.5093 | U8: 2179.3648 | V8: 2207.21 | W8: 2235.0656 | X8: 2262.9212 | Y8: 2290.7768 | Z8: 2318.6324 | AA8: 2346.488 | AB8: 2375.0501 | AC8: 2402.9057 | AD8: 2430.7613 | AE8: 2458.6169 | AF8: 2486.4725 | AG8: 2514.328 | AH8: 2542.1836 | AI8: 2570.0392 | AJ8: 2597.8948 | AK8: 2626.4465
A9: 2500 | B9: 1666.4833 | C9: 1694.3389 | D9: 1722.1944 | E9: 1750.0396 | F9: 1777.8952 | G9: 1805.7508 | H9: 1833.6064 | I9: 1861.462 | J9: 1890.0241 | K9: 1917.8797 | L9: 1945.7353 | M9: 1973.5909 | N9: 2001.4465 | O9: 2049.6041 | P9: 2077.4597 | Q9: 2105.3153 | R9: 2133.1709 | S9: 2161.733 | T9: 2189.5886 | U9: 2217.4338 | V9: 2245.2894 | W9: 2273.145 | X9: 2301.0006 | Y9: 2328.8562 | Z9: 2356.7117 | AA9: 2384.5673 | AB9: 2413.1294 | AC9: 2440.985 | AD9: 2468.8406 | AE9: 2496.6962 | AF9: 2524.5518 | AG9: 2552.4074 | AH9: 2580.263 | AI9: 2608.1186 | AJ9: 2635.9638 | AK9: 2664.5259
A10: 2600 | B10: 1704.5626 | C10: 1732.4182 | D10: 1760.2634 | E10: 1788.119 | F10: 1815.9746 | G10: 1843.8302 | H10: 1871.6858 | I10: 1899.5414 | J10: 1928.1035 | K10: 1955.9591 | L10: 1983.8146 | M10: 2011.6702 | N10: 2059.8279 | O10: 2087.6835 | P10: 2115.5391 | Q10: 2143.3947 | R10: 2171.2399 | S10: 2199.802 | T10: 2227.6576 | U10: 2255.5131 | V10: 2283.3687 | W10: 2311.2243 | X10: 2339.0799 | Y10: 2366.9355 | Z10: 2394.7911 | AA10: 2422.6467 | AB10: 2451.2088 | AC10: 2479.0644 | AD10: 2506.92 | AE10: 2534.7756 | AF10: 2562.6312 | AG10: 2590.4868 | AH10: 2618.3319 | AI10: 2646.1875 | AJ10: 2674.0431 | AK10: 2702.6052
A11: 2700 | B11: 1742.6316 | C11: 1770.4872 | D11: 1798.3428 | E11: 1826.1983 | F11: 1854.0539 | G11: 1881.9095 | H11: 1909.7651 | I11: 1937.6207 | J11: 1966.1828 | K11: 1994.0384 | L11: 2021.894 | M11: 2070.0516 | N11: 2097.9072 | O11: 2125.7628 | P11: 2153.608 | Q11: 2181.4636 | R11: 2209.3192 | S11: 2237.8813 | T11: 2265.7369 | U11: 2293.5925 | V11: 2321.4481 | W11: 2349.3037 | X11: 2377.1593 | Y11: 2405.0149 | Z11: 2432.8704 | AA11: 2460.726 | AB11: 2489.2881 | AC11: 2517.1437 | AD11: 2544.9993 | AE11: 2572.8445 | AF11: 2600.7001 | AG11: 2628.5557 | AH11: 2656.4113 | AI11: 2684.2669 | AJ11: 2712.1225 | AK11: 2740.6846
C13: patio_3_
B14: 2250 | C14: 2350 | D14: 2450 | E14: 2550 | F14: 2650 | G14: 2750 | H14: 2850 | I14: 2950 | J14: 3050 | K14: 3150 | L14: 3250 | M14: 3350 | N14: 3450 | O14: 3550 | P14: 3650 | Q14: 3750 | R14: 3850 | S14: 3950 | T14: 4050 | U14: 4150 | V14: 4250 | W14: 4350 | X14: 4450 | Y14: 4550 | Z14: 4650 | AA14: 4750 | AB14: 4850 | AC14: 4950 | AD14: 5050 | AE14: 5150 | AF14: 5250 | AG14: 5350 | AH14: 5450 | AI14: 5550 | AJ14: 5650 | AK14: 5750 | AL14: 5850 | AM14: 5950 | AN14: 6050 | AO14: 6150 | AP14: 6250 | AQ14: 6350 | AR14: 6450 | AS14: 6550 | AT14: 6650 | AU14: 6750 | AV14: 6850 | AW14: 6950 | AX14: 7050 | AY14: 7150 | AZ14: 7250 | BA14: 7350 | BB14: 7450 | BC14: 7500
A15: 2000 | B15: 2190.212 | C15: 2223.9795 | D15: 2257.747 | E15: 2291.5145 | F15: 2325.282 | G15: 2359.0495 | H15: 2392.817 | I15: 2426.5845 | J15: 2460.3416 | K15: 2494.1091 | L15: 2528.9364 | M15: 2562.7039 | N15: 2596.4714 | O15: 2630.2389 | P15: 2664.0064 | Q15: 2697.7635 | R15: 2731.531 | S15: 2765.2985 | T15: 2799.066 | U15: 2832.8335 | V15: 2866.601 | W15: 2900.3685 | X15: 2934.1256 | Y15: 2967.8931 | Z15: 3002.7204 | AA15: 3036.4879 | AB15: 3070.2554 | AC15: 3104.0229 | AD15: 3137.7904 | AE15: 3212.162 | AF15: 3245.9191 | AG15: 3279.6866 | AH15: 3313.4541 | AI15: 3347.2216 | AJ15: 3380.9891 | AK15: 3414.7566 | AL15: 3448.5241 | AM15: 3483.341 | AN15: 3517.1085 | AO15: 3550.876 | AP15: 3584.6435 | AQ15: 3618.411 | AR15: 3652.1785 | AS15: 3685.946 | AT15: 3719.7031 | AU15: 3753.4706 | AV15: 3787.2381 | AW15: 3821.0056 | AX15: 3854.7731 | AY15: 3888.5406 | AZ15: 3922.3081 | BA15: 3957.1354 | BB15: 3990.8925 | BC15: 4007.7763
A16: 2100 | B16: 2243.4919 | C16: 2277.2594 | D16: 2311.0269 | E16: 2344.7944 | F16: 2378.5619 | G16: 2412.3294 | H16: 2446.0865 | I16: 2479.854 | J16: 2513.6215 | K16: 2547.389 | L16: 2582.2163 | M16: 2615.9838 | N16: 2649.7513 | O16: 2683.5084 | P16: 2717.2759 | Q16: 2751.0434 | R16: 2784.8109 | S16: 2818.5784 | T16: 2852.3459 | U16: 2886.1134 | V16: 2919.8705 | W16: 2953.638 | X16: 2987.4055 | Y16: 3021.173 | Z16: 3056.0003 | AA16: 3089.7678 | AB16: 3143.8374 | AC16: 3197.8965 | AD16: 3231.664 | AE16: 3265.4315 | AF16: 3299.199 | AG16: 3332.9665 | AH16: 3366.734 | AI16: 3400.5015 | AJ16: 3434.269 | AK16: 3468.0261 | AL16: 3501.7936 | AM16: 3536.6209 | AN16: 3570.3884 | AO16: 3604.1559 | AP16: 3637.9234 | AQ16: 3671.6909 | AR16: 3705.448 | AS16: 3739.2155 | AT16: 3772.983 | AU16: 3806.7505 | AV16: 3840.518 | AW16: 3874.2855 | AX16: 3908.053 | AY16: 3941.8101 | AZ16: 3975.5776 | BA16: 4010.4049 | BB16: 4044.1724 | BC16: 4061.0562
A17: 2200 | B17: 2296.7718 | C17: 2330.5393 | D17: 2364.3068 | E17: 2398.064 | F17: 2431.8315 | G17: 2465.599 | H17: 2499.3664 | I17: 2533.1339 | J17: 2566.9014 | K17: 2600.669 | L17: 2635.4858 | M17: 2669.2533 | N17: 2703.0208 | O17: 2736.7883 | P17: 2770.5558 | Q17: 2804.3233 | R17: 2838.0908 | S17: 2871.8479 | T17: 2905.6154 | U17: 2939.383 | V17: 2973.1505 | W17: 3006.918 | X17: 3040.6854 | Y17: 3074.4529 | Z17: 3149.8843 | AA17: 3183.6415 | AB17: 3217.409 | AC17: 3251.1765 | AD17: 3284.944 | AE17: 3318.7115 | AF17: 3352.479 | AG17: 3386.2465 | AH17: 3420.014 | AI17: 3453.7711 | AJ17: 3487.5386 | AK17: 3521.3061 | AL17: 3555.0736 | AM17: 3589.9008 | AN17: 3623.6683 | AO17: 3657.4358 | AP17: 3691.193 | AQ17: 3724.9605 | AR17: 3758.728 | AS17: 3792.4955 | AT17: 3826.263 | AU17: 3860.0305 | AV17: 3893.798 | AW17: 3927.5551 | AX17: 3961.3226 | AY17: 3995.0901 | AZ17: 4028.8576 | BA17: 4063.6848 | BB17: 4097.4523 | BC17: 4114.3361
A18: 2300 | B18: 2350.0518 | C18: 2383.8089 | D18: 2417.5764 | E18: 2451.3439 | F18: 2485.1114 | G18: 2518.8789 | H18: 2552.6464 | I18: 2586.4139 | J18: 2620.171 | K18: 2653.9385 | L18: 2688.7658 | M18: 2722.5333 | N18: 2756.3008 | O18: 2790.0683 | P18: 2823.8358 | Q18: 2857.5929 | R18: 2891.3604 | S18: 2925.1279 | T18: 2958.8954 | U18: 2992.6629 | V18: 3026.4304 | W18: 3060.1979 | X18: 3134.5591 | Y18: 3168.3266 | Z18: 3203.1539 | AA18: 3236.9214 | AB18: 3270.6889 | AC18: 3304.4564 | AD18: 3338.2239 | AE18: 3371.9914 | AF18: 3405.7485 | AG18: 3439.516 | AH18: 3473.2835 | AI18: 3507.051 | AJ18: 3540.8185 | AK18: 3574.586 | AL18: 3608.3535 | AM18: 3643.1704 | AN18: 3676.9379 | AO18: 3710.7054 | AP18: 3744.4729 | AQ18: 3778.2404 | AR18: 3812.0079 | AS18: 3845.7754 | AT18: 3879.5325 | AU18: 3913.3 | AV18: 3947.0675 | AW18: 3980.835 | AX18: 4014.6025 | AY18: 4048.37 | AZ18: 4082.1375 | BA18: 4116.9648 | BB18: 4150.7219 | BC18: 4167.6056
A19: 2400 | B19: 2403.3213 | C19: 2437.0888 | D19: 2470.8563 | E19: 2504.6238 | F19: 2538.3913 | G19: 2572.1588 | H19: 2605.9159 | I19: 2639.6834 | J19: 2673.4509 | K19: 2707.2184 | L19: 2742.0457 | M19: 2775.8132 | N19: 2809.5807 | O19: 2843.3378 | P19: 2877.1053 | Q19: 2910.8728 | R19: 2944.6403 | S19: 2978.4078 | T19: 3012.1753 | U19: 3045.9428 | V19: 3120.3144 | W19: 3154.0715 | X19: 3187.839 | Y19: 3221.6065 | Z19: 3256.4338 | AA19: 3290.2013 | AB19: 3323.9688 | AC19: 3357.7259 | AD19: 3391.4934 | AE19: 3425.2609 | AF19: 3459.0284 | AG19: 3492.7959 | AH19: 3526.5634 | AI19: 3560.3309 | AJ19: 3594.0984 | AK19: 3627.8555 | AL19: 3661.623 | AM19: 3696.4503 | AN19: 3730.2178 | AO19: 3763.9853 | AP19: 3797.7528 | AQ19: 3831.5203 | AR19: 3865.2774 | AS19: 3899.0449 | AT19: 3932.8124 | AU19: 3966.5799 | AV19: 4000.3474 | AW19: 4034.1149 | AX19: 4067.8824 | AY19: 4101.6499 | AZ19: 4135.407 | BA19: 4170.2343 | BB19: 4204.0018 | BC19: 4220.8855
A20: 2500 | B20: 2456.6012 | C20: 2490.3687 | D20: 2524.1362 | E20: 2557.8933 | F20: 2591.6608 | G20: 2625.4283 | H20: 2659.1958 | I20: 2692.9633 | J20: 2726.7308 | K20: 2760.4983 | L20: 2795.3256 | M20: 2829.0827 | N20: 2862.8502 | O20: 2896.6177 | P20: 2930.3852 | Q20: 2964.1527 | R20: 2997.9202 | S20: 3031.6877 | T20: 3085.7469 | U20: 3139.8164 | V20: 3173.5839 | W20: 3207.3514 | X20: 3241.1189 | Y20: 3274.8864 | Z20: 3309.7137 | AA20: 3343.4708 | AB20: 3377.2383 | AC20: 3411.0058 | AD20: 3444.7733 | AE20: 3478.5408 | AF20: 3512.3083 | AG20: 3546.0758 | AH20: 3579.8433 | AI20: 3613.6004 | AJ20: 3647.3679 | AK20: 3681.1354 | AL20: 3714.9029 | AM20: 3749.7302 | AN20: 3783.4977 | AO20: 3817.2652 | AP20: 3851.0223 | AQ20: 3884.7898 | AR20: 3918.5573 | AS20: 3952.3248 | AT20: 3986.0923 | AU20: 4019.8598 | AV20: 4053.6273 | AW20: 4087.3844 | AX20: 4121.1519 | AY20: 4154.9194 | AZ20: 4188.6869 | BA20: 4223.5142 | BB20: 4257.2817 | BC20: 4274.1655
A21: 2600 | B21: 2509.8811 | C21: 2543.6382 | D21: 2577.4057 | E21: 2611.1732 | F21: 2644.9407 | G21: 2678.7082 | H21: 2712.4757 | I21: 2746.2432 | J21: 2780.0003 | K21: 2813.7678 | L21: 2848.5951 | M21: 2882.3626 | N21: 2916.1301 | O21: 2949.8976 | P21: 2983.6651 | Q21: 3017.4222 | R21: 3071.4918 | S21: 3125.5614 | T21: 3159.3289 | U21: 3193.0964 | V21: 3226.8639 | W21: 3260.6314 | X21: 3294.3885 | Y21: 3328.156 | Z21: 3362.9832 | AA21: 3396.7507 | AB21: 3430.5182 | AC21: 3464.2857 | AD21: 3498.0532 | AE21: 3531.8207 | AF21: 3565.5779 | AG21: 3599.3454 | AH21: 3633.1129 | AI21: 3666.8804 | AJ21: 3700.6479 | AK21: 3734.4154 | AL21: 3768.1829 | AM21: 3802.9997 | AN21: 3836.7672 | AO21: 3870.5347 | AP21: 3904.3022 | AQ21: 3938.0697 | AR21: 3971.8372 | AS21: 4005.6047 | AT21: 4039.3619 | AU21: 4073.1294 | AV21: 4106.8969 | AW21: 4140.6644 | AX21: 4174.4319 | AY21: 4208.1994 | AZ21: 4241.9669 | BA21: 4276.7837 | BB21: 4310.5512 | BC21: 4327.435
A22: 2700 | B22: 2563.1507 | C22: 2596.9182 | D22: 2630.6857 | E22: 2664.4532 | F22: 2698.2207 | G22: 2731.9882 | H22: 2765.7453 | I22: 2799.5128 | J22: 2833.2803 | K22: 2867.0478 | L22: 2901.875 | M22: 2935.6425 | N22: 2969.41 | O22: 3003.1672 | P22: 3036.9347 | Q22: 3111.3063 | R22: 3145.0738 | S22: 3178.8413 | T22: 3212.6088 | U22: 3246.3763 | V22: 3280.1334 | W22: 3313.9009 | X22: 3347.6684 | Y22: 3381.4359 | Z22: 3416.2632 | AA22: 3450.0307 | AB22: 3483.7982 | AC22: 3517.5553 | AD22: 3551.3228 | AE22: 3585.0903 | AF22: 3618.8578 | AG22: 3652.6253 | AH22: 3686.3928 | AI22: 3720.1603 | AJ22: 3753.9278 | AK22: 3787.6849 | AL22: 3821.4524 | AM22: 3856.2797 | AN22: 3890.0472 | AO22: 3923.8147 | AP22: 3957.5822 | AQ22: 3991.3497 | AR22: 4025.1068 | AS22: 4058.8743 | AT22: 4092.6418 | AU22: 4126.4093 | AV22: 4160.1768 | AW22: 4193.9443 | AX22: 4227.7118 | AY22: 4261.4793 | AZ22: 4295.2364 | BA22: 4330.0637 | BB22: 4363.8312 | BC22: 4342.5628
C24: patio_4_
B25: 2800 | C25: 2900 | D25: 3000 | E25: 3100 | F25: 3200 | G25: 3300 | H25: 3400 | I25: 3500 | J25: 3600 | K25: 3700 | L25: 3800 | M25: 3900 | N25: 4000 | O25: 4100 | P25: 4200 | Q25: 4300 | R25: 4400 | S25: 4500 | T25: 4600 | U25: 4700 | V25: 4800 | W25: 4900 | X25: 5000 | Y25: 5100 | Z25: 5200 | AA25: 5300 | AB25: 5400 | AC25: 5500 | AD25: 5600 | AE25: 5700 | AF25: 5800 | AG25: 5900 | AH25: 6000 | AI25: 6100 | AJ25: 6200 | AK25: 6300 | AL25: 6400 | AM25: 6500 | AN25: 6600 | AO25: 6700 | AP25: 6800 | AQ25: 6900 | AR25: 7000 | AS25: 7100 | AT25: 7200 | AU25: 7300 | AV25: 7400 | AW25: 7500 | AX25: 7600 | AY25: 7700 | AZ25: 7800 | BA25: 7900 | BB25: 8000 | BC25: 8100 | BD25: 8200 | BE25: 8300 | BF25: 8400 | BG25: 8500 | BH25: 8600 | BI25: 8700 | BJ25: 8800 | BK25: 8900 | BL25: 9000 | BM25: 9100 | BN25: 9200 | BO25: 9300 | BP25: 9400 | BQ25: 9500 | BR25: 9600 | BS25: 9700 | BT25: 9800 | BU25: 9900 | BV25: 10000
A26: 2000 | B26: 2573.2393 | C26: 2601.0949 | D26: 2628.9505 | E26: 2656.8061 | F26: 2684.6617 | G26: 2712.5173 | H26: 2740.3625 | I26: 2768.2181 | J26: 2796.0737 | K26: 2823.9293 | L26: 2851.7849 | M26: 2879.6404 | N26: 2907.496 | O26: 2935.3516 | P26: 2963.2072 | Q26: 2991.0628 | R26: 3020.3314 | S26: 3048.187 | T26: 3076.0426 | U26: 3103.8982 | V26: 3131.7538 | W26: 3159.599 | X26: 3187.4546 | Y26: 3215.3102 | Z26: 3243.1658 | AA26: 3271.0214 | AB26: 3298.8769 | AC26: 3326.7325 | AD26: 3354.5881 | AE26: 3382.4437 | AF26: 3410.2993 | AG26: 3438.1549 | AH26: 3466.0105 | AI26: 3493.8661 | AJ26: 3523.1347 | AK26: 3550.9903 | AL26: 3578.8355 | AM26: 3606.6911 | AN26: 3634.5467 | AO26: 3682.7043 | AP26: 3710.5599 | AQ26: 3758.7176 | AR26: 3786.5732 | AS26: 3814.4287 | AT26: 3842.2843 | AU26: 3870.1399 | AV26: 3897.9955 | AW26: 3925.8511 | AX26: 3953.7067 | AY26: 3981.5623 | AZ26: 4009.4075 | BA26: 4037.2631 | BB26: 4066.5317 | BC26: 4094.3873 | BD26: 4122.2429 | BE26: 4150.0985 | BF26: 4177.9541 | BG26: 4205.8097 | BH26: 4233.6653 | BI26: 4261.5208 | BJ26: 4289.3764 | BK26: 4317.232 | BL26: 4345.0876 | BM26: 4372.9432 | BN26: 4400.7884 | BO26: 4428.6544 | BP26: 4456.4996 | BQ26: 4484.3552 | BR26: 4512.2108 | BS26: 4540.0663 | BT26: 4569.335 | BU26: 4597.1906 | BV26: 4625.0462
A27: 2100 | B27: 2636.8054 | C27: 2664.661 | D27: 2692.5165 | E27: 2720.3721 | F27: 2748.2277 | G27: 2776.0833 | H27: 2803.9389 | I27: 2831.7945 | J27: 2859.6501 | K27: 2887.5057 | L27: 2915.3509 | M27: 2943.2065 | N27: 2971.0621 | O27: 2998.9176 | P27: 3026.7732 | Q27: 3054.6288 | R27: 3083.8975 | S27: 3111.753 | T27: 3139.6086 | U27: 3167.4642 | V27: 3195.3198 | W27: 3223.1754 | X27: 3251.031 | Y27: 3278.8866 | Z27: 3306.7318 | AA27: 3334.5874 | AB27: 3362.443 | AC27: 3390.2986 | AD27: 3418.1541 | AE27: 3446.0097 | AF27: 3473.8653 | AG27: 3501.7209 | AH27: 3529.5765 | AI27: 3557.4321 | AJ27: 3586.7007 | AK27: 3634.8584 | AL27: 3662.714 | AM27: 3710.8716 | AN27: 3738.7168 | AO27: 3766.5828 | AP27: 3794.428 | AQ27: 3822.2836 | AR27: 3850.1392 | AS27: 3877.9948 | AT27: 3905.8504 | AU27: 3933.706 | AV27: 3961.5615 | AW27: 3989.4171 | AX27: 4017.2727 | AY27: 4045.1283 | AZ27: 4072.9839 | BA27: 4100.8395 | BB27: 4130.1081 | BC27: 4157.9637 | BD27: 4185.8089 | BE27: 4213.6645 | BF27: 4241.5201 | BG27: 4269.3757 | BH27: 4297.2313 | BI27: 4325.0869 | BJ27: 4352.9424 | BK27: 4380.798 | BL27: 4408.6536 | BM27: 4436.5092 | BN27: 4464.3648 | BO27: 4492.2204 | BP27: 4520.076 | BQ27: 4547.9316 | BR27: 4575.7872 | BS27: 4603.6324 | BT27: 4632.9114 | BU27: 4660.7566 | BV27: 4688.6122
A28: 2200 | B28: 2700.3714 | C28: 2728.227 | D28: 2756.0826 | E28: 2783.9382 | F28: 2811.7937 | G28: 2839.6493 | H28: 2867.5049 | I28: 2895.3605 | J28: 2923.2161 | K28: 2951.0717 | L28: 2978.9273 | M28: 3006.7829 | N28: 3034.6385 | O28: 3062.4941 | P28: 3090.3393 | Q28: 3118.2052 | R28: 3147.4635 | S28: 3175.3191 | T28: 3203.1747 | U28: 3231.0302 | V28: 3258.8858 | W28: 3286.7414 | X28: 3314.597 | Y28: 3342.4526 | Z28: 3370.3082 | AA28: 3398.1638 | AB28: 3426.0194 | AC28: 3453.875 | AD28: 3481.7202 | AE28: 3509.5758 | AF28: 3537.4313 | AG28: 3565.2869 | AH28: 3613.4446 | AI28: 3641.3002 | AJ28: 3690.8709 | AK28: 3718.7265 | AL28: 3746.582 | AM28: 3774.4376 | AN28: 3802.2932 | AO28: 3830.1488 | AP28: 3858.0044 | AQ28: 3885.86 | AR28: 3913.7156 | AS28: 3941.5712 | AT28: 3969.4268 | AU28: 3997.272 | AV28: 4025.1276 | AW28: 4052.9831 | AX28: 4080.8387 | AY28: 4108.6943 | AZ28: 4136.5499 | BA28: 4164.4055 | BB28: 4193.6741 | BC28: 4221.5297 | BD28: 4249.3853 | BE28: 4277.2409 | BF28: 4305.0965 | BG28: 4332.9521 | BH28: 4360.8077 | BI28: 4388.6529 | BJ28: 4416.5085 | BK28: 4444.3641 | BL28: 4472.2197 | BM28: 4500.0752 | BN28: 4527.9308 | BO28: 4555.7864 | BP28: 4583.642 | BQ28: 4611.4976 | BR28: 4639.3532 | BS28: 4667.2088 | BT28: 4696.4774 | BU28: 4724.333 | BV28: 4752.1886
A29: 2300 | B29: 2763.9478 | C29: 2791.8034 | D29: 2819.659 | E29: 2847.5042 | F29: 2875.3598 | G29: 2903.2154 | H29: 2931.0709 | I29: 2958.9265 | J29: 2986.7821 | K29: 3014.6377 | L29: 3042.4933 | M29: 3070.3489 | N29: 3098.2045 | O29: 3126.0601 | P29: 3153.9157 | Q29: 3181.7713 | R29: 3211.0399 | S29: 3238.8851 | T29: 3266.7511 | U29: 3294.5963 | V29: 3322.4519 | W29: 3350.3074 | X29: 3378.163 | Y29: 3406.0186 | Z29: 3433.8742 | AA29: 3461.7298 | AB29: 3489.5854 | AC29: 3517.441 | AD29: 3545.2966 | AE29: 3593.4542 | AF29: 3621.3098 | AG29: 3669.4675 | AH29: 3697.3231 | AI29: 3725.1683 | AJ29: 3754.4473 | AK29: 3782.2925 | AL29: 3810.1481 | AM29: 3838.0037 | AN29: 3865.8592 | AO29: 3893.7148 | AP29: 3921.5704 | AQ29: 3949.426 | AR29: 3977.2816 | AS29: 4005.1372 | AT29: 4032.9928 | AU29: 4060.8484 | AV29: 4088.704 | AW29: 4116.5492 | AX29: 4144.4151 | AY29: 4172.2603 | AZ29: 4200.1159 | BA29: 4227.9715 | BB29: 4257.2402 | BC29: 4285.0957 | BD29: 4312.9513 | BE29: 4340.8069 | BF29: 4368.6625 | BG29: 4396.5181 | BH29: 4424.3737 | BI29: 4452.2293 | BJ29: 4480.0849 | BK29: 4507.9405 | BL29: 4535.7857 | BM29: 4563.6413 | BN29: 4591.4968 | BO29: 4619.3524 | BP29: 4647.208 | BQ29: 4675.0636 | BR29: 4702.9192 | BS29: 4730.7748 | BT29: 4760.0434 | BU29: 4787.899 | BV29: 4815.7546
A30: 2400 | B30: 2827.5138 | C30: 2855.3694 | D30: 2883.225 | E30: 2911.0806 | F30: 2938.9362 | G30: 2966.7918 | H30: 2994.6474 | I30: 3022.4926 | J30: 3050.3481 | K30: 3078.2037 | L30: 3106.0593 | M30: 3133.9149 | N30: 3161.7705 | O30: 3189.6261 | P30: 3217.4817 | Q30: 3245.3373 | R30: 3274.6059 | S30: 3302.4615 | T30: 3330.3171 | U30: 3358.1727 | V30: 3386.0283 | W30: 3413.8839 | X30: 3441.7291 | Y30: 3469.5846 | Z30: 3497.4402 | AA30: 3525.2958 | AB30: 3553.1514 | AC30: 3601.3091 | AD30: 3629.1647 | AE30: 3677.3223 | AF30: 3705.1779 | AG30: 3733.0335 | AH30: 3760.8891 | AI30: 3788.7447 | AJ30: 3818.0133 | AK30: 3845.8689 | AL30: 3873.7245 | AM30: 3901.5697 | AN30: 3929.4253 | AO30: 3957.2809 | AP30: 3985.1364 | AQ30: 4012.992 | AR30: 4040.8476 | AS30: 4068.7032 | AT30: 4096.5588 | AU30: 4124.4144 | AV30: 4152.27 | AW30: 4180.1256 | AX30: 4207.9812 | AY30: 4235.8368 | AZ30: 4263.6923 | BA30: 4291.5479 | BB30: 4320.8062 | BC30: 4348.6722 | BD30: 4376.5174 | BE30: 4404.3729 | BF30: 4432.2285 | BG30: 4460.0841 | BH30: 4487.9397 | BI30: 4515.7953 | BJ30: 4543.6509 | BK30: 4571.5065 | BL30: 4599.3621 | BM30: 4627.2177 | BN30: 4655.0733 | BO30: 4682.9288 | BP30: 4710.7844 | BQ30: 4738.64 | BR30: 4766.4852 | BS30: 4794.3408 | BT30: 4823.6094 | BU30: 4851.465 | BV30: 4879.3206
A31: 2500 | B31: 2891.0798 | C31: 2918.9354 | D31: 2946.791 | E31: 2974.6466 | F31: 3002.5022 | G31: 3030.3578 | H31: 3058.2134 | I31: 3086.069 | J31: 3113.9246 | K31: 3141.7801 | L31: 3169.6357 | M31: 3197.4913 | N31: 3225.3365 | O31: 3253.1921 | P31: 3281.0477 | Q31: 3308.9033 | R31: 3338.1719 | S31: 3366.0275 | T31: 3393.8831 | U31: 3421.7387 | V31: 3449.5943 | W31: 3477.4499 | X31: 3505.3055 | Y31: 3533.1611 | Z31: 3581.3187 | AA31: 3609.1743 | AB31: 3657.3319 | AC31: 3685.1875 | AD31: 3713.0327 | AE31: 3740.8883 | AF31: 3768.7439 | AG31: 3796.5995 | AH31: 3824.4551 | AI31: 3852.3107 | AJ31: 3881.5793 | AK31: 3909.4349 | AL31: 3937.2905 | AM31: 3965.1461 | AN31: 3993.0017 | AO31: 4020.8573 | AP31: 4048.7129 | AQ31: 4076.5684 | AR31: 4104.4136 | AS31: 4132.2692 | AT31: 4160.1248 | AU31: 4187.9804 | AV31: 4215.836 | AW31: 4243.6916 | AX31: 4271.5472 | AY31: 4299.4028 | AZ31: 4327.2584 | BA31: 4355.114 | BB31: 4384.3826 | BC31: 4412.2382 | BD31: 4440.0938 | BE31: 4467.939 | BF31: 4495.7946 | BG31: 4523.6502 | BH31: 4551.5057 | BI31: 4579.3613 | BJ31: 4607.2169 | BK31: 4635.0725 | BL31: 4662.9281 | BM31: 4690.7837 | BN31: 4718.6393 | BO31: 4746.4949 | BP31: 4774.3505 | BQ31: 4802.206 | BR31: 4830.0616 | BS31: 4857.9172 | BT31: 4887.1859 | BU31: 4915.0311 | BV31: 4942.8867
A32: 2600 | B32: 2954.6562 | C32: 2982.5014 | D32: 3010.357 | E32: 3038.2126 | F32: 3066.0682 | G32: 3093.9238 | H32: 3121.7794 | I32: 3149.635 | J32: 3177.4906 | K32: 3205.3462 | L32: 3233.2018 | M32: 3261.0574 | N32: 3288.9129 | O32: 3316.7685 | P32: 3344.6137 | Q32: 3372.4797 | R32: 3401.7379 | S32: 3429.5935 | T32: 3457.4491 | U32: 3485.3047 | V32: 3513.1603 | W32: 3541.0159 | X32: 3589.1735 | Y32: 3617.0291 | Z32: 3665.1868 | AA32: 3693.0424 | AB32: 3720.898 | AC32: 3748.7536 | AD32: 3776.6091 | AE32: 3804.4543 | AF32: 3832.3203 | AG32: 3860.1655 | AH32: 3888.0211 | AI32: 3915.8767 | AJ32: 3945.1453 | AK32: 3973.0009 | AL32: 4000.8565 | AM32: 4028.7121 | AN32: 4056.5677 | AO32: 4084.4233 | AP32: 4112.2789 | AQ32: 4140.1345 | AR32: 4167.9901 | AS32: 4195.8456 | AT32: 4223.7012 | AU32: 4251.5464 | AV32: 4279.402 | AW32: 4307.2576 | AX32: 4335.1132 | AY32: 4362.9688 | AZ32: 4390.8244 | BA32: 4418.68 | BB32: 4447.9486 | BC32: 4475.8042 | BD32: 4503.6598 | BE32: 4531.5154 | BF32: 4559.371 | BG32: 4587.2266 | BH32: 4615.0822 | BI32: 4642.9377 | BJ32: 4670.7933 | BK32: 4698.6385 | BL32: 4726.4941 | BM32: 4754.3497 | BN32: 4782.2053 | BO32: 4810.0609 | BP32: 4837.9165 | BQ32: 4865.7721 | BR32: 4893.6277 | BS32: 4921.4832 | BT32: 4950.7519 | BU32: 4978.6075 | BV32: 5006.4631
A33: 2700 | B33: 3018.2223 | C33: 3046.0779 | D33: 3073.9334 | E33: 3101.789 | F33: 3129.6446 | G33: 3157.4898 | H33: 3185.3454 | I33: 3213.201 | J33: 3241.0566 | K33: 3268.9122 | L33: 3296.7678 | M33: 3324.6234 | N33: 3352.479 | O33: 3380.3345 | P33: 3408.1901 | Q33: 3436.0457 | R33: 3465.3144 | S33: 3493.1699 | T33: 3521.0255 | U33: 3548.8707 | V33: 3597.0388 | W33: 3624.884 | X33: 3673.0416 | Y33: 3700.8972 | Z33: 3728.7528 | AA33: 3756.6084 | AB33: 3784.464 | AC33: 3812.3196 | AD33: 3840.1752 | AE33: 3868.0308 | AF33: 3895.8863 | AG33: 3923.7419 | AH33: 3951.5975 | AI33: 3979.4531 | AJ33: 4008.7217 | AK33: 4036.5773 | AL33: 4064.4225 | AM33: 4092.2781 | AN33: 4120.1337 | AO33: 4147.9893 | AP33: 4175.8449 | AQ33: 4203.7005 | AR33: 4231.5561 | AS33: 4259.4117 | AT33: 4287.2673 | AU33: 4315.1228 | AV33: 4342.9784 | AW33: 4370.834 | AX33: 4398.6896 | AY33: 4426.5452 | AZ33: 4454.3904 | BA33: 4482.246 | BB33: 4511.5146 | BC33: 4539.3702 | BD33: 4567.2258 | BE33: 4595.0814 | BF33: 4622.937 | BG33: 4650.7926 | BH33: 4678.6482 | BI33: 4706.5038 | BJ33: 4734.3593 | BK33: 4762.2149 | BL33: 4790.0705 | BM33: 4817.9261 | BN33: 4845.7713 | BO33: 4873.6269 | BP33: 4901.4825 | BQ33: 4929.3381 | BR33: 4957.1937 | BS33: 4985.0493 | BT33: 5014.3179 | BU33: 5004.0214 | BV33: 5031.877
C35: patio_mono_2_
B36: 1500 | C36: 1600 | D36: 1700 | E36: 1800 | F36: 1900 | G36: 2000 | H36: 2100 | I36: 2200 | J36: 2300 | K36: 2400 | L36: 2500 | M36: 2600 | N36: 2700 | O36: 2800 | P36: 2900 | Q36: 3000 | R36: 3100 | S36: 3200 | T36: 3300 | U36: 3400 | V36: 3500 | W36: 3600 | X36: 3700 | Y36: 3800 | Z36: 3900 | AA36: 4000 | AB36: 4100 | AC36: 4200 | AD36: 4300 | AE36: 4400 | AF36: 4500 | AG36: 4600 | AH36: 4700 | AI36: 4800 | AJ36: 4900 | AK36: 5000
A37: 2000 | B37: 1190.7875 | C37: 1211.1 | D37: 1231.402 | E37: 1251.7145 | F37: 1272.0269 | G37: 1292.3394 | H37: 1312.6518 | I37: 1333.6708 | J37: 1353.9832 | K37: 1374.2957 | L37: 1394.6081 | M37: 1414.9102 | N37: 1435.2226 | O37: 1455.5351 | P37: 1475.8475 | Q37: 1496.16 | R37: 1517.179 | S37: 1537.4914 | T37: 1557.8039 | U37: 1598.4184 | V37: 1618.7204 | W37: 1639.0329 | X37: 1659.3453 | Y37: 1679.6578 | Z37: 1699.9702 | AA37: 1720.9892 | AB37: 1741.3017 | AC37: 1761.6141 | AD37: 1781.9266 | AE37: 1802.2286 | AF37: 1822.5411 | AG37: 1842.8535 | AH37: 1863.166 | AI37: 1883.4784 | AJ37: 1904.4974 | AK37: 1924.8098
A38: 2100 | B38: 1221.251 | C38: 1241.5634 | D38: 1261.8759 | E38: 1282.1883 | F38: 1302.4904 | G38: 1322.8029 | H38: 1343.1153 | I38: 1364.1343 | J38: 1384.4467 | K38: 1404.7592 | L38: 1425.0716 | M38: 1445.3841 | N38: 1465.6965 | O38: 1485.9986 | P38: 1506.311 | Q38: 1526.6235 | R38: 1547.6424 | S38: 1588.257 | T38: 1608.5694 | U38: 1628.8819 | V38: 1649.1943 | W38: 1669.5068 | X38: 1689.8192 | Y38: 1710.1213 | Z38: 1730.4337 | AA38: 1751.4527 | AB38: 1771.7651 | AC38: 1792.0776 | AD38: 1812.39 | AE38: 1832.7025 | AF38: 1853.0149 | AG38: 1873.3274 | AH38: 1893.6294 | AI38: 1913.9419 | AJ38: 1934.9609 | AK38: 1955.2733
A39: 2200 | B39: 1251.7145 | C39: 1272.0269 | D39: 1292.3394 | E39: 1312.6518 | F39: 1332.9643 | G39: 1353.2767 | H39: 1373.5892 | I39: 1394.5977 | J39: 1414.9102 | K39: 1435.2226 | L39: 1455.5351 | M39: 1475.8475 | N39: 1496.16 | O39: 1516.4724 | P39: 1536.7849 | Q39: 1557.0974 | R39: 1598.408 | S39: 1618.7204 | T39: 1639.0329 | U39: 1659.3453 | V39: 1679.6578 | W39: 1699.9702 | X39: 1720.2827 | Y39: 1740.5951 | Z39: 1760.9076 | AA39: 1781.9162 | AB39: 1802.2286 | AC39: 1822.5411 | AD39: 1842.8535 | AE39: 1863.166 | AF39: 1883.4784 | AG39: 1903.7909 | AH39: 1924.1033 | AI39: 1944.4158 | AJ39: 1965.4244 | AK39: 1985.7368
A40: 2300 | B40: 1282.1779 | C40: 1302.4904 | D40: 1322.8029 | E40: 1343.1153 | F40: 1363.4277 | G40: 1383.7402 | H40: 1404.0526 | I40: 1425.0716 | J40: 1445.3841 | K40: 1465.6861 | L40: 1485.9986 | M40: 1506.311 | N40: 1526.6235 | O40: 1546.9359 | P40: 1587.5504 | Q40: 1607.8629 | R40: 1628.8819 | S40: 1649.1943 | T40: 1669.4964 | U40: 1689.8088 | V40: 1710.1213 | W40: 1730.4337 | X40: 1750.7462 | Y40: 1771.0586 | Z40: 1791.3711 | AA40: 1812.39 | AB40: 1832.7025 | AC40: 1853.0045 | AD40: 1873.317 | AE40: 1893.6294 | AF40: 1913.9419 | AG40: 1934.2543 | AH40: 1954.5668 | AI40: 1974.8792 | AJ40: 1995.8982 | AK40: 2016.2107
A41: 2400 | B41: 1312.6518 | C41: 1332.9643 | D41: 1353.2767 | E41: 1373.5788 | F41: 1393.8912 | G41: 1414.2037 | H41: 1434.5161 | I41: 1455.5351 | J41: 1475.8475 | K41: 1496.16 | L41: 1516.4724 | M41: 1536.7849 | N41: 1557.087 | O41: 1597.7015 | P41: 1618.0139 | Q41: 1638.3264 | R41: 1659.3453 | S41: 1679.6578 | T41: 1699.9702 | U41: 1720.2827 | V41: 1740.5951 | W41: 1760.8972 | X41: 1781.2096 | Y41: 1801.5221 | Z41: 1821.8345 | AA41: 1842.8535 | AB41: 1863.166 | AC41: 1883.4784 | AD41: 1903.7909 | AE41: 1924.1033 | AF41: 1944.4054 | AG41: 1964.7178 | AH41: 1985.0303 | AI41: 2005.3427 | AJ41: 2026.3617 | AK41: 2046.6741
A42: 2500 | B42: 1343.1153 | C42: 1363.4277 | D42: 1383.7402 | E42: 1404.0526 | F42: 1424.3651 | G42: 1444.6672 | H42: 1464.9796 | I42: 1485.9986 | J42: 1506.311 | K42: 1526.6235 | L42: 1546.9359 | M42: 1567.2484 | N42: 1607.8629 | O42: 1628.1753 | P42: 1648.4774 | Q42: 1668.7898 | R42: 1689.8088 | S42: 1710.1213 | T42: 1730.4337 | U42: 1750.7462 | V42: 1771.0586 | W42: 1791.3711 | X42: 1811.6835 | Y42: 1831.9856 | Z42: 1852.298 | AA42: 1873.317 | AB42: 1893.6294 | AC42: 1913.9419 | AD42: 1934.2543 | AE42: 1954.5668 | AF42: 1974.8792 | AG42: 1995.1917 | AH42: 2015.5041 | AI42: 2035.8062 | AJ42: 2056.8252 | AK42: 2077.1376
A43: 2600 | B43: 1373.5788 | C43: 1393.8912 | D43: 1414.2037 | E43: 1434.5161 | F43: 1454.8286 | G43: 1475.141 | H43: 1495.4535 | I43: 1516.4724 | J43: 1536.7745 | K43: 1557.087 | L43: 1577.3994 | M43: 1618.0139 | N43: 1638.3264 | O43: 1658.6388 | P43: 1678.9513 | Q43: 1699.2637 | R43: 1720.2827 | S43: 1740.5847 | T43: 1760.8972 | U43: 1781.2096 | V43: 1801.5221 | W43: 1821.8345 | X43: 1842.147 | Y43: 1862.4594 | Z43: 1882.7719 | AA43: 1903.7909 | AB43: 1924.0929 | AC43: 1944.4054 | AD43: 1964.7178 | AE43: 1985.0303 | AF43: 2005.3427 | AG43: 2025.6552 | AH43: 2045.9676 | AI43: 2066.2801 | AJ43: 2087.2991 | AK43: 2107.6011
A44: 2700 | B44: 1404.0526 | C44: 1424.3547 | D44: 1444.6672 | E44: 1464.9796 | F44: 1485.2921 | G44: 1505.6045 | H44: 1525.917 | I44: 1546.9359 | J44: 1567.2484 | K44: 1587.5608 | L44: 1628.1649 | M44: 1648.4774 | N44: 1668.7898 | O44: 1689.1023 | P44: 1709.4147 | Q44: 1729.7272 | R44: 1750.7462 | S44: 1771.0586 | T44: 1791.3711 | U44: 1811.6731 | V44: 1831.9856 | W44: 1852.298 | X44: 1872.6105 | Y44: 1892.9229 | Z44: 1913.2354 | AA44: 1934.2543 | AB44: 1954.5668 | AC44: 1974.8792 | AD44: 1995.1917 | AE44: 2015.4938 | AF44: 2035.8062 | AG44: 2056.1187 | AH44: 2076.4311 | AI44: 2096.7436 | AJ44: 2117.7625 | AK44: 2099.9229
...

Sheet patio_2
A1: type | B1: matrix | C1: patio_2_
A2: ='(patio_costs)'!A3 | B2: ='(patio_costs)'!B3 -> 1500 | C2: ='(patio_costs)'!C3 -> 1600 | D2: ='(patio_costs)'!D3 -> 1700 | E2: ='(patio_costs)'!E3 -> 1800 | F2: ='(patio_costs)'!F3 -> 1900 | G2: ='(patio_costs)'!G3 -> 2000 | H2: ='(patio_costs)'!H3 -> 2100 | ... AK2: ='(patio_costs)'!AK3 -> 5000
A3: ='(patio_costs)'!A4 -> 2000 | B3: {='(patio_costs)'!B4:AK11*(1+MARKUP!$Z$6)} -> 1110.755106 | C3: 1131.7164 | D3: 1152.6778 | E3: 1173.6391 | F3: 1194.6004 | G3: 1215.5618 | H3: 1236.5231 | I3: 1257.4844 | J3: 1278.9774 | K3: 1299.9387 | L3: 1320.9001 | M3: 1341.8614 | N3: 1362.8227 | O3: 1383.7841 | P3: 1404.7376 | Q3: 1425.6989 | R3: 1446.6602 | S3: 1468.1532 | T3: 1489.1146 | U3: 1510.0759 | V3: 1546.3145 | W3: 1567.2759 | X3: 1588.2372 | Y3: 1609.1985 | Z3: 1630.1599 | AA3: 1651.1212 | AB3: 1672.6142 | AC3: 1693.5755 | AD3: 1714.5368 | AE3: 1735.4904 | AF3: 1756.4517 | AG3: 1777.413 | AH3: 1798.3743 | AI3: 1819.3357 | AJ3: 1840.297 | AK3: 1861.79
A4: ='(patio_costs)'!A5 -> 2100 | B4: 1139.4098 | C4: 1160.3711 | D4: 1181.3325 | E4: 1202.2938 | F4: 1223.2551 | G4: 1244.2165 | H4: 1265.1778 | I4: 1286.1391 | J4: 1307.6321 | K4: 1328.5935 | L4: 1349.5548 | M4: 1370.5161 | N4: 1391.4696 | O4: 1412.431 | P4: 1433.3923 | Q4: 1454.3536 | R4: 1475.315 | S4: 1496.8079 | T4: 1533.0466 | U4: 1554.0079 | V4: 1574.9692 | W4: 1595.9306 | X4: 1616.8919 | Y4: 1637.8532 | Z4: 1658.8146 | AA4: 1679.7759 | AB4: 1701.2689 | AC4: 1722.2224 | AD4: 1743.1837 | AE4: 1764.1451 | AF4: 1785.1064 | AG4: 1806.0677 | AH4: 1827.0291 | AI4: 1847.9904 | AJ4: 1868.9517 | AK4: 1890.4447
A5: ='(patio_costs)'!A6 -> 2200 | B5: 1168.0645 | C5: 1189.0259 | D5: 1209.9872 | E5: 1230.9485 | F5: 1251.9099 | G5: 1272.8712 | H5: 1293.8325 | I5: 1314.7938 | J5: 1336.2868 | K5: 1357.2482 | L5: 1378.2017 | M5: 1399.163 | N5: 1420.1243 | O5: 1441.0857 | P5: 1462.047 | Q5: 1483.0083 | R5: 1503.9697 | S5: 1540.74 | T5: 1561.7013 | U5: 1582.6626 | V5: 1603.624 | W5: 1624.5853 | X5: 1645.5466 | Y5: 1666.5079 | Z5: 1687.4693 | AA5: 1708.4228 | AB5: 1729.9158 | AC5: 1750.8771 | AD5: 1771.8384 | AE5: 1792.7998 | AF5: 1813.7611 | AG5: 1834.7224 | AH5: 1855.6838 | AI5: 1876.6451 | AJ5: 1897.6064 | AK5: 1919.0994
A6: ='(patio_costs)'!A7 -> 2300 | B6: 1196.7192 | C6: 1217.6806 | D6: 1238.6419 | E6: 1259.6032 | F6: 1280.5646 | G6: 1301.5259 | H6: 1322.4872 | I6: 1343.4486 | J6: 1364.9337 | K6: 1385.8951 | L6: 1406.8564 | M6: 1427.8177 | N6: 1448.7791 | O6: 1469.7404 | P6: 1490.7017 | Q6: 1526.9403 | R6: 1547.9017 | S6: 1569.3947 | T6: 1590.356 | U6: 1611.3173 | V6: 1632.2787 | W6: 1653.24 | X6: 1674.2013 | Y6: 1695.1548 | Z6: 1716.1162 | AA6: 1737.0775 | AB6: 1758.5705 | AC6: 1779.5318 | AD6: 1800.4932 | AE6: 1821.4545 | AF6: 1842.4158 | AG6: 1863.3771 | AH6: 1884.3385 | AI6: 1905.2998 | AJ6: 1926.2611 | AK6: 1947.7541
A7: ='(patio_costs)'!A8 -> 2400 | B7: 1225.3739 | C7: 1246.3353 | D7: 1267.2966 | E7: 1288.2579 | F7: 1309.2193 | G7: 1330.1806 | H7: 1351.1341 | I7: 1372.0955 | J7: 1393.5884 | K7: 1414.5498 | L7: 1435.5111 | M7: 1456.4724 | N7: 1477.4338 | O7: 1498.3951 | P7: 1534.6337 | Q7: 1555.5951 | R7: 1576.5564 | S7: 1598.0494 | T7: 1619.0107 | U7: 1639.972 | V7: 1660.9256 | W7: 1681.8869 | X7: 1702.8482 | Y7: 1723.8095 | Z7: 1744.7709 | AA7: 1765.7322 | AB7: 1787.2252 | AC7: 1808.1865 | AD7: 1829.1479 | AE7: 1850.1092 | AF7: 1871.0705 | AG7: 1892.0319 | AH7: 1912.9932 | AI7: 1933.9545 | AJ7: 1954.9159 | AK7: 1976.401
A8: ='(patio_costs)'!A9 -> 2500 | B8: 1254.0287 | C8: 1274.99 | D8: 1295.9513 | E8: 1316.9048 | F8: 1337.8662 | G8: 1358.8275 | H8: 1379.7888 | I8: 1400.7502 | J8: 1422.2432 | K8: 1443.2045 | L8: 1464.1658 | M8: 1485.1271 | N8: 1506.0885 | O8: 1542.3271 | P8: 1563.2884 | Q8: 1584.2498 | R8: 1605.2111 | S8: 1626.7041 | T8: 1647.6654 | U8: 1668.6189 | V8: 1689.5803 | W8: 1710.5416 | X8: 1731.5029 | Y8: 1752.4643 | Z8: 1773.4256 | AA8: 1794.3869 | AB8: 1815.8799 | AC8: 1836.8412 | AD8: 1857.8026 | AE8: 1878.7639 | AF8: 1899.7252 | AG8: 1920.6866 | AH8: 1941.6479 | AI8: 1962.6092 | AJ8: 1983.5627 | AK8: 2005.0557
A9: ='(patio_costs)'!A10 -> 2600 | B9: 1282.6834 | C9: 1303.6447 | D9: 1324.5982 | E9: 1345.5595 | F9: 1366.5209 | G9: 1387.4822 | H9: 1408.4435 | I9: 1429.4049 | J9: 1450.8979 | K9: 1471.8592 | L9: 1492.8205 | M9: 1513.7819 | N9: 1550.0205 | O9: 1570.9818 | P9: 1591.9432 | Q9: 1612.9045 | R9: 1633.858 | S9: 1655.351 | T9: 1676.3123 | U9: 1697.2736 | V9: 1718.235 | W9: 1739.1963 | X9: 1760.1576 | Y9: 1781.119 | Z9: 1802.0803 | AA9: 1823.0416 | AB9: 1844.5346 | AC9: 1865.496 | AD9: 1886.4573 | AE9: 1907.4186 | AF9: 1928.3799 | AG9: 1949.3413 | AH9: 1970.2948 | AI9: 1991.2561 | AJ9: 2012.2175 | AK9: 2033.7104
A10: ='(patio_costs)'!A11 -> 2700 | B10: 1311.3303 | C10: 1332.2916 | D10: 1353.2529 | E10: 1374.2143 | F10: 1395.1756 | G10: 1416.1369 | H10: 1437.0983 | I10: 1458.0596 | J10: 1479.5526 | K10: 1500.5139 | L10: 1521.4752 | M10: 1557.7139 | N10: 1578.6752 | O10: 1599.6365 | P10: 1620.59 | Q10: 1641.5514 | R10: 1662.5127 | S10: 1684.0057 | T10: 1704.967 | U10: 1725.9284 | V10: 1746.8897 | W10: 1767.851 | X10: 1788.8124 | Y10: 1809.7737 | Z10: 1830.735 | AA10: 1851.6963 | AB10: 1873.1893 | AC10: 1894.1507 | AD10: 1915.112 | AE10: 1936.0655 | AF10: 1957.0268 | AG10: 1977.9882 | AH10: 1998.9495 | AI10: 2019.9108 | AJ10: 2040.8722 | AK10: 2062.3652

Sheet patio_3
A1: type | B1: matrix | C1: patio_3_
A2: ='(patio_costs)'!A14 | B2: ='(patio_costs)'!B14 -> 2250 | C2: ='(patio_costs)'!C14 -> 2350 | D2: ='(patio_costs)'!D14 -> 2450 | E2: ='(patio_costs)'!E14 -> 2550 | F2: ='(patio_costs)'!F14 -> 2650 | G2: ='(patio_costs)'!G14 -> 2750 | H2: ='(patio_costs)'!H14 -> 2850 | ... BC2: ='(patio_costs)'!BC14 -> 7500
A3: ='(patio_costs)'!A15 -> 2000 | B3: {='(patio_costs)'!B15:BC22*(1+MARKUP!$Z$6)} -> 1648.13453 | C3: 1673.5446 | D3: 1698.9546 | E3: 1724.3647 | F3: 1749.7747 | G3: 1775.1847 | H3: 1800.5948 | I3: 1826.0048 | J3: 1851.4071 | K3: 1876.8171 | L3: 1903.0246 | M3: 1928.4347 | N3: 1953.8447 | O3: 1979.2548 | P3: 2004.6648 | Q3: 2030.067 | R3: 2055.4771 | S3: 2080.8871 | T3: 2106.2972 | U3: 2131.7072 | V3: 2157.1173 | W3: 2182.5273 | X3: 2207.9295 | Y3: 2233.3396 | Z3: 2259.5471 | AA3: 2284.9571 | AB3: 2310.3672 | AC3: 2335.7772 | AD3: 2361.1873 | AE3: 2417.1519 | AF3: 2442.5541 | AG3: 2467.9642 | AH3: 2493.3742 | AI3: 2518.7843 | AJ3: 2544.1943 | AK3: 2569.6044 | AL3: 2595.0144 | AM3: 2621.2141 | AN3: 2646.6242 | AO3: 2672.0342 | AP3: 2697.4442 | AQ3: 2722.8543 | AR3: 2748.2643 | AS3: 2773.6744 | AT3: 2799.0766 | AU3: 2824.4866 | AV3: 2849.8967 | AW3: 2875.3067 | AX3: 2900.7168 | AY3: 2926.1268 | AZ3: 2951.5369 | BA3: 2977.7444 | BB3: 3003.1466 | BC3: 3015.8516
A4: ='(patio_costs)'!A16 -> 2100 | B4: 1688.2277 | C4: 1713.6377 | D4: 1739.0478 | E4: 1764.4578 | F4: 1789.8678 | G4: 1815.2779 | H4: 1840.6801 | I4: 1866.0902 | J4: 1891.5002 | K4: 1916.9102 | L4: 1943.1178 | M4: 1968.5278 | N4: 1993.9379 | O4: 2019.3401 | P4: 2044.7501 | Q4: 2070.1602 | R4: 2095.5702 | S4: 2120.9803 | T4: 2146.3903 | U4: 2171.8003 | V4: 2197.2026 | W4: 2222.6126 | X4: 2248.0227 | Y4: 2273.4327 | Z4: 2299.6402 | AA4: 2325.0503 | AB4: 2365.7376 | AC4: 2406.4171 | AD4: 2431.8272 | AE4: 2457.2372 | AF4: 2482.6473 | AG4: 2508.0573 | AH4: 2533.4674 | AI4: 2558.8774 | AJ4: 2584.2875 | AK4: 2609.6897 | AL4: 2635.0997 | AM4: 2661.3072 | AN4: 2686.7173 | AO4: 2712.1273 | AP4: 2737.5374 | AQ4: 2762.9474 | AR4: 2788.3497 | AS4: 2813.7597 | AT4: 2839.1697 | AU4: 2864.5798 | AV4: 2889.9898 | AW4: 2915.3999 | AX4: 2940.8099 | AY4: 2966.2121 | AZ4: 2991.6222 | BA4: 3017.8297 | BB4: 3043.2398 | BC4: 3055.9448
A5: ='(patio_costs)'!A17 -> 2200 | B5: 1728.3208 | C5: 1753.7309 | D5: 1779.1409 | E5: 1804.5431 | F5: 1829.9532 | G5: 1855.3632 | H5: 1880.7733 | I5: 1906.1833 | J5: 1931.5933 | K5: 1957.0034 | L5: 1983.2031 | M5: 2008.6131 | N5: 2034.0232 | O5: 2059.4332 | P5: 2084.8433 | Q5: 2110.2533 | R5: 2135.6634 | S5: 2161.0656 | T5: 2186.4756 | U5: 2211.8857 | V5: 2237.2957 | W5: 2262.7058 | X5: 2288.1158 | Y5: 2313.5258 | Z5: 2370.288 | AA5: 2395.6902 | AB5: 2421.1002 | AC5: 2446.5103 | AD5: 2471.9203 | AE5: 2497.3304 | AF5: 2522.7404 | AG5: 2548.1505 | AH5: 2573.5605 | AI5: 2598.9627 | AJ5: 2624.3728 | AK5: 2649.7828 | AL5: 2675.1929 | AM5: 2701.4004 | AN5: 2726.8104 | AO5: 2752.2205 | AP5: 2777.6227 | AQ5: 2803.0327 | AR5: 2828.4428 | AS5: 2853.8528 | AT5: 2879.2629 | AU5: 2904.6729 | AV5: 2930.083 | AW5: 2955.4852 | AX5: 2980.8952 | AY5: 3006.3053 | AZ5: 3031.7153 | BA5: 3057.9228 | BB5: 3083.3329 | BC5: 3096.0379
A6: ='(patio_costs)'!A18 -> 2300 | B6: 1768.4139 | C6: 1793.8162 | D6: 1819.2262 | E6: 1844.6363 | F6: 1870.0463 | G6: 1895.4563 | H6: 1920.8664 | I6: 1946.2764 | J6: 1971.6787 | K6: 1997.0887 | L6: 2023.2962 | M6: 2048.7063 | N6: 2074.1163 | O6: 2099.5264 | P6: 2124.9364 | Q6: 2150.3386 | R6: 2175.7487 | S6: 2201.1587 | T6: 2226.5688 | U6: 2251.9788 | V6: 2277.3889 | W6: 2302.7989 | X6: 2358.7557 | Y6: 2384.1658 | Z6: 2410.3733 | AA6: 2435.7833 | AB6: 2461.1934 | AC6: 2486.6034 | AD6: 2512.0135 | AE6: 2537.4235 | AF6: 2562.8257 | AG6: 2588.2358 | AH6: 2613.6458 | AI6: 2639.0559 | AJ6: 2664.4659 | AK6: 2689.876 | AL6: 2715.286 | AM6: 2741.4857 | AN6: 2766.8958 | AO6: 2792.3058 | AP6: 2817.7158 | AQ6: 2843.1259 | AR6: 2868.5359 | AS6: 2893.946 | AT6: 2919.3482 | AU6: 2944.7582 | AV6: 2970.1683 | AW6: 2995.5783 | AX6: 3020.9884 | AY6: 3046.3984 | AZ6: 3071.8085 | BA6: 3098.016 | BB6: 3123.4182 | BC6: 3136.1232
A7: ='(patio_costs)'!A19 -> 2400 | B7: 1808.4993 | C7: 1833.9093 | D7: 1859.3194 | E7: 1884.7294 | F7: 1910.1394 | G7: 1935.5495 | H7: 1960.9517 | I7: 1986.3618 | J7: 2011.7718 | K7: 2037.1818 | L7: 2063.3894 | M7: 2088.7994 | N7: 2114.2095 | O7: 2139.6117 | P7: 2165.0217 | Q7: 2190.4318 | R7: 2215.8418 | S7: 2241.2519 | T7: 2266.6619 | U7: 2292.0719 | V7: 2348.0366 | W7: 2373.4388 | X7: 2398.8489 | Y7: 2424.2589 | Z7: 2450.4664 | AA7: 2475.8765 | AB7: 2501.2865 | AC7: 2526.6887 | AD7: 2552.0988 | AE7: 2577.5088 | AF7: 2602.9189 | AG7: 2628.3289 | AH7: 2653.739 | AI7: 2679.149 | AJ7: 2704.5591 | AK7: 2729.9613 | AL7: 2755.3713 | AM7: 2781.5789 | AN7: 2806.9889 | AO7: 2832.3989 | AP7: 2857.809 | AQ7: 2883.219 | AR7: 2908.6213 | AS7: 2934.0313 | AT7: 2959.4413 | AU7: 2984.8514 | AV7: 3010.2614 | AW7: 3035.6715 | AX7: 3061.0815 | AY7: 3086.4916 | AZ7: 3111.8938 | BA7: 3138.1013 | BB7: 3163.5114 | BC7: 3176.2164
A8: ='(patio_costs)'!A20 -> 2500 | B8: 1848.5924 | C8: 1874.0025 | D8: 1899.4125 | E8: 1924.8147 | F8: 1950.2248 | G8: 1975.6348 | H8: 2001.0449 | I8: 2026.4549 | J8: 2051.8649 | K8: 2077.275 | L8: 2103.4825 | M8: 2128.8847 | N8: 2154.2948 | O8: 2179.7048 | P8: 2205.1149 | Q8: 2230.5249 | R8: 2255.935 | S8: 2281.345 | T8: 2322.0245 | U8: 2362.7119 | V8: 2388.1219 | W8: 2413.532 | X8: 2438.942 | Y8: 2464.352 | Z8: 2490.5596 | AA8: 2515.9618 | AB8: 2541.3718 | AC8: 2566.7819 | AD8: 2592.1919 | AE8: 2617.602 | AF8: 2643.012 | AG8: 2668.4221 | AH8: 2693.8321 | AI8: 2719.2343 | AJ8: 2744.6444 | AK8: 2770.0544 | AL8: 2795.4645 | AM8: 2821.672 | AN8: 2847.082 | AO8: 2872.4921 | AP8: 2897.8943 | AQ8: 2923.3043 | AR8: 2948.7144 | AS8: 2974.1244 | AT8: 2999.5345 | AU8: 3024.9445 | AV8: 3050.3546 | AW8: 3075.7568 | AX8: 3101.1668 | AY8: 3126.5769 | AZ8: 3151.9869 | BA8: 3178.1945 | BB8: 3203.6045 | BC8: 3216.3095
A9: ='(patio_costs)'!A21 -> 2600 | B9: 1888.6856 | C9: 1914.0878 | D9: 1939.4978 | E9: 1964.9079 | F9: 1990.3179 | G9: 2015.728 | H9: 2041.138 | I9: 2066.548 | J9: 2091.9503 | K9: 2117.3603 | L9: 2143.5678 | M9: 2168.9779 | N9: 2194.3879 | O9: 2219.798 | P9: 2245.208 | Q9: 2270.6102 | R9: 2311.2976 | S9: 2351.9849 | T9: 2377.395 | U9: 2402.805 | V9: 2428.2151 | W9: 2453.6251 | X9: 2479.0273 | Y9: 2504.4374 | Z9: 2530.6449 | AA9: 2556.0549 | AB9: 2581.465 | AC9: 2606.875 | AD9: 2632.2851 | AE9: 2657.6951 | AF9: 2683.0973 | AG9: 2708.5074 | AH9: 2733.9174 | AI9: 2759.3275 | AJ9: 2784.7375 | AK9: 2810.1476 | AL9: 2835.5576 | AM9: 2861.7573 | AN9: 2887.1674 | AO9: 2912.5774 | AP9: 2937.9874 | AQ9: 2963.3975 | AR9: 2988.8075 | AS9: 3014.2176 | AT9: 3039.6198 | AU9: 3065.0298 | AV9: 3090.4399 | AW9: 3115.8499 | AX9: 3141.26 | AY9: 3166.67 | AZ9: 3192.0801 | BA9: 3218.2798 | BB9: 3243.6898 | BC9: 3256.3948
A10: ='(patio_costs)'!A22 -> 2700 | B10: 1928.7709 | C10: 1954.1809 | D10: 1979.591 | E10: 2005.001 | F10: 2030.411 | G10: 2055.8211 | H10: 2081.2233 | I10: 2106.6334 | J10: 2132.0434 | K10: 2157.4534 | L10: 2183.661 | M10: 2209.071 | N10: 2234.4811 | O10: 2259.8833 | P10: 2285.2933 | Q10: 2341.258 | R10: 2366.668 | S10: 2392.0781 | T10: 2417.4881 | U10: 2442.8982 | V10: 2468.3004 | W10: 2493.7104 | X10: 2519.1205 | Y10: 2544.5305 | Z10: 2570.738 | AA10: 2596.1481 | AB10: 2621.5581 | AC10: 2646.9603 | AD10: 2672.3704 | AE10: 2697.7804 | AF10: 2723.1905 | AG10: 2748.6005 | AH10: 2774.0106 | AI10: 2799.4206 | AJ10: 2824.8307 | AK10: 2850.2329 | AL10: 2875.6429 | AM10: 2901.8505 | AN10: 2927.2605 | AO10: 2952.6705 | AP10: 2978.0806 | AQ10: 3003.4906 | AR10: 3028.8929 | AS10: 3054.3029 | AT10: 3079.7129 | AU10: 3105.123 | AV10: 3130.533 | AW10: 3155.9431 | AX10: 3181.3531 | AY10: 3206.7632 | AZ10: 3232.1654 | BA10: 3258.3729 | BB10: 3283.783 | BC10: 3267.7785

Sheet patio_4
A1: type | B1: matrix | C1: patio_4_
A2: ='(patio_costs)'!A25 | B2: ='(patio_costs)'!B25 -> 2800 | C2: ='(patio_costs)'!C25 -> 2900 | D2: ='(patio_costs)'!D25 -> 3000 | E2: ='(patio_costs)'!E25 -> 3100 | F2: ='(patio_costs)'!F25 -> 3200 | G2: ='(patio_costs)'!G25 -> 3300 | H2: ='(patio_costs)'!H25 -> 3400 | ... BV2: ='(patio_costs)'!BV25 -> 10000
A3: ='(patio_costs)'!A26 -> 2000 | B3: {='(patio_costs)'!B26:BV33*(1+MARKUP!$Z$6)} -> 1936.362611 | C3: 1957.3239 | D3: 1978.2853 | E3: 1999.2466 | F3: 2020.2079 | G3: 2041.1693 | H3: 2062.1228 | I3: 2083.0841 | J3: 2104.0454 | K3: 2125.0068 | L3: 2145.9681 | M3: 2166.9294 | N3: 2187.8908 | O3: 2208.8521 | P3: 2229.8134 | Q3: 2250.7748 | R3: 2272.7994 | S3: 2293.7607 | T3: 2314.7221 | U3: 2335.6834 | V3: 2356.6447 | W3: 2377.5982 | X3: 2398.5596 | Y3: 2419.5209 | Z3: 2440.4822 | AA3: 2461.4436 | AB3: 2482.4049 | AC3: 2503.3662 | AD3: 2524.3276 | AE3: 2545.2889 | AF3: 2566.2502 | AG3: 2587.2116 | AH3: 2608.1729 | AI3: 2629.1342 | AJ3: 2651.1589 | AK3: 2672.1202 | AL3: 2693.0737 | AM3: 2714.035 | AN3: 2734.9964 | AO3: 2771.235 | AP3: 2792.1963 | AQ3: 2828.435 | AR3: 2849.3963 | AS3: 2870.3576 | AT3: 2891.319 | AU3: 2912.2803 | AV3: 2933.2416 | AW3: 2954.203 | AX3: 2975.1643 | AY3: 2996.1256 | AZ3: 3017.0791 | BA3: 3038.0405 | BB3: 3060.0651 | BC3: 3081.0264 | BD3: 3101.9878 | BE3: 3122.9491 | BF3: 3143.9104 | BG3: 3164.8718 | BH3: 3185.8331 | BI3: 3206.7944 | BJ3: 3227.7558 | BK3: 3248.7171 | BL3: 3269.6784 | BM3: 3290.6398 | BN3: 3311.5933 | BO3: 3332.5624 | BP3: 3353.5159 | BQ3: 3374.4773 | BR3: 3395.4386 | BS3: 3416.3999 | BT3: 3438.4246 | BU3: 3459.3859 | BV3: 3480.3472
